<?xml version="1.0"?>
<!--  
*****************************************************************************************
*
*  Filename:			quad.xacro
*  Created:				22/12/2023
*  Last Modified:	22/12/2023
*  Author:				Archit Jain
*  
*****************************************************************************************
-->
<robot name="quad" xmlns:xacro="http://www.ros.org/wiki/xacro">

  <!-- ****************** INCLUDE OTHER MACROS ***************************  -->
  <xacro:include filename="$(find quad_description)/models/quad/quad_gazebo.xacro" />

  <!-- ****************** BASIC INERTIAL MACROS ***************************  -->
  <!-- Define intertial property macros  -->
  <xacro:macro name="box_inertia" params="m w h d *origin">
    <inertial>
      <xacro:insert_block name="origin"/>
      <mass value="${m}"/>
      <inertia  ixx="${(m/12) * (h*h + d*d)}" ixy="0.0" ixz="0.0" 
                iyy="${(m/12) * (w*w + d*d)}" iyz="0.0" 
                izz="${(m/12) * (w*w + h*h)}"/>
    </inertial>
  </xacro:macro>
  <xacro:macro name="cylinder_inertia" params="m r h">
    <inertial>
      <origin xyz="0 0 0" rpy="${pi/2} 0 0" />
      <mass value="${m}"/>
      <inertia ixx="${(m/12) * (3*r*r + h*h)}" ixy = "0" ixz = "0" iyy="${(m/12) * (3*r*r + h*h)}" iyz = "0" izz="${(m/2) * (r*r)}"/>
    </inertial>
  </xacro:macro>
  <xacro:macro name="sphere_inertia" params="m r">
    <inertial>
      <mass value="${m}"/>
      <inertia ixx="${(2/5) * m * (r*r)}" ixy="0.0" ixz="0.0" iyy="${(2/5) * m * (r*r)}" iyz="0.0" izz="${(2/5) * m * (r*r)}"/>
    </inertial>
  </xacro:macro>

  <!-- ****************** ROBOT CONSTANTS *******************************  -->
  <!-- Define the size of the robot's main chassis in meters -->
  <xacro:property name="base_width" value="0.550"/>
  <xacro:property name="base_length" value="0.325"/>
  <xacro:property name="base_height" value="0.025"/>
  <xacro:property name="base_mass" value="0.4"/>
  <xacro:property name="quad_height" value="1.0"/>
  <xacro:property name="joint_limit" value="2.00712863979"/>      <!-- 115 degree -->

  <!-- ****************** ROBOT BASE FOOTPRINT ***************************  -->
  <!-- Define the center of the main robot chassis projected on the ground -->	
  <link name="base_footprint" />


  <!-- The base footprint of the robot is located underneath the chassis -->
  <joint name="base_joint" type="fixed">
    <origin xyz="0 0 ${quad_height}" rpy="1.571428571 0 0"/>
    <parent link="base_footprint"/>
    <child link="base_link" />
  </joint>

  <!-- ********************** ROBOT BASE *********************************  -->
  <link name="base_link">
    <visual>
      <origin xyz="0 0 0" rpy="0 0 0"/>
      <geometry>
        <mesh filename="file://$(find quad_description)/meshes/base.obj" scale=".001 .001 .001"/>
      </geometry>
    </visual>
    <collision>
      <origin xyz="0 0 0" rpy="0 0 0"/>
      <geometry>
        <mesh filename="file://$(find quad_description)/meshes/base.obj" scale=".001 .001 .001"/>
      </geometry>
    </collision>
    <xacro:box_inertia m="0.02" w="0.060" d="0.110" h="0.110">
      <origin xyz="0 0.030 0" rpy="1.571428571 0 0"/>
    </xacro:box_inertia>
  </link>

  <joint name="thigh_joint" type="revolute">
    <origin xyz="0 0 0" rpy="0 0 0"/>
    <parent link="base_link"/>
    <child link="thigh_link" />
    <axis xyz="0 0 1" />
    <limit effort="1.5" lower="-${joint_limit}" upper="${joint_limit}" velocity="1.0"/>
    <dynamics damping="10.0" friction="1000.0" />
  </joint>

  <!-- ********************** THIGH LINK *********************************  -->
  <link name="thigh_link">
    <visual>
      <origin xyz="0 0 0" rpy="0 0 0"/>
      <geometry>
        <mesh filename="file://$(find quad_description)/meshes/thigh.obj" scale=".001 .001 .001"/>
      </geometry>
    </visual>
    <collision>
      <origin xyz="0 0 0" rpy="0 0 0"/>
      <geometry>
        <mesh filename="file://$(find quad_description)/meshes/thigh.obj" scale=".001 .001 .001"/>
      </geometry>
    </collision>
    <xacro:box_inertia m="0.015" w="0.050" d="0.270" h="0.110">
      <origin xyz="0 -0.110 0" rpy="1.571428571 0 0"/>
    </xacro:box_inertia>
  </link>

  <joint name="leg_joint" type="revolute">
    <origin xyz="0 -0.220 0" rpy="0 0 0"/>
    <parent link="thigh_link"/>
    <child link="leg_link" />
    <axis xyz="0 0 1" />
    <limit effort="1.5" lower="-${joint_limit}" upper="${joint_limit}" velocity="1.0"/>
    <dynamics damping="10.0" friction="1000.0" />
  </joint>

  <!-- ********************** LEG LINK *********************************  -->
  <link name="leg_link">
    <visual>
      <origin xyz="0 0 0" rpy="0 0 0"/>
      <geometry>
        <mesh filename="file://$(find quad_description)/meshes/leg.obj" scale=".001 .001 .001"/>
      </geometry>
    </visual>
    <collision>
      <origin xyz="0 0 0" rpy="0 0 0"/>
      <geometry>
        <mesh filename="file://$(find quad_description)/meshes/leg.obj" scale=".001 .001 .001"/>
      </geometry>
    </collision>
    <xacro:box_inertia m="0.0125" w="0.050" d="0.200" h="0.060">
      <origin xyz="0 -0.075 0" rpy="1.571428571 0 0"/>
    </xacro:box_inertia>
  </link>

</robot>
